[2024-06-04T22:46:42.700+0000] {local_task_job_runner.py:120} INFO - ::group::Pre task execution logs
[2024-06-04T22:46:42.719+0000] {taskinstance.py:2076} INFO - Dependencies all met for dep_context=non-requeueable deps ti=<TaskInstance: ingestion_data.conectando_con_redshift manual__2024-06-04T22:46:32.936015+00:00 [queued]>
[2024-06-04T22:46:42.726+0000] {taskinstance.py:2076} INFO - Dependencies all met for dep_context=requeueable deps ti=<TaskInstance: ingestion_data.conectando_con_redshift manual__2024-06-04T22:46:32.936015+00:00 [queued]>
[2024-06-04T22:46:42.726+0000] {taskinstance.py:2306} INFO - Starting attempt 1 of 2
[2024-06-04T22:46:42.736+0000] {taskinstance.py:2330} INFO - Executing <Task(PythonOperator): conectando_con_redshift> on 2024-06-04 22:46:32.936015+00:00
[2024-06-04T22:46:42.744+0000] {warnings.py:110} WARNING - /home/***/.local/lib/python3.12/site-packages/***/task/task_runner/standard_task_runner.py:61: DeprecationWarning: This process (pid=78) is multi-threaded, use of fork() may lead to deadlocks in the child.
  pid = os.fork()

[2024-06-04T22:46:42.746+0000] {standard_task_runner.py:63} INFO - Started process 80 to run task
[2024-06-04T22:46:42.747+0000] {standard_task_runner.py:90} INFO - Running: ['***', 'tasks', 'run', 'ingestion_data', 'conectando_con_redshift', 'manual__2024-06-04T22:46:32.936015+00:00', '--job-id', '13', '--raw', '--subdir', 'DAGS_FOLDER/entregable_dag.py', '--cfg-path', '/tmp/tmpwxrv6j5c']
[2024-06-04T22:46:42.748+0000] {standard_task_runner.py:91} INFO - Job 13: Subtask conectando_con_redshift
[2024-06-04T22:46:42.792+0000] {task_command.py:426} INFO - Running <TaskInstance: ingestion_data.conectando_con_redshift manual__2024-06-04T22:46:32.936015+00:00 [running]> on host fd0d5636e48d
[2024-06-04T22:46:42.860+0000] {taskinstance.py:2648} INFO - Exporting env vars: AIRFLOW_CTX_DAG_OWNER='Guillermo Hern√°ndez' AIRFLOW_CTX_DAG_ID='ingestion_data' AIRFLOW_CTX_TASK_ID='conectando_con_redshift' AIRFLOW_CTX_EXECUTION_DATE='2024-06-04T22:46:32.936015+00:00' AIRFLOW_CTX_TRY_NUMBER='1' AIRFLOW_CTX_DAG_RUN_ID='manual__2024-06-04T22:46:32.936015+00:00'
[2024-06-04T22:46:42.861+0000] {taskinstance.py:430} INFO - ::endgroup::
[2024-06-04T22:46:42.862+0000] {logging_mixin.py:188} INFO - Error connecting
[2024-06-04T22:46:42.862+0000] {logging_mixin.py:188} INFO - connection to server on socket "/var/run/postgresql/.s.PGSQL.5439" failed: No such file or directory
	Is the server running locally and accepting connections on that socket?
[2024-06-04T22:46:42.862+0000] {taskinstance.py:441} INFO - ::group::Post task execution logs
[2024-06-04T22:46:42.863+0000] {taskinstance.py:2905} ERROR - Task failed with exception
Traceback (most recent call last):
  File "/home/airflow/.local/lib/python3.12/site-packages/airflow/models/taskinstance.py", line 465, in _execute_task
    result = _execute_callable(context=context, **execute_callable_kwargs)
             ^^^^^^^^^^^^^^^^^^^^^^^^^^^^^^^^^^^^^^^^^^^^^^^^^^^^^^^^^^^^^
  File "/home/airflow/.local/lib/python3.12/site-packages/airflow/models/taskinstance.py", line 432, in _execute_callable
    return execute_callable(context=context, **execute_callable_kwargs)
           ^^^^^^^^^^^^^^^^^^^^^^^^^^^^^^^^^^^^^^^^^^^^^^^^^^^^^^^^^^^^
  File "/home/airflow/.local/lib/python3.12/site-packages/airflow/models/baseoperator.py", line 400, in wrapper
    return func(self, *args, **kwargs)
           ^^^^^^^^^^^^^^^^^^^^^^^^^^^
  File "/home/airflow/.local/lib/python3.12/site-packages/airflow/operators/python.py", line 235, in execute
    return_value = self.execute_callable()
                   ^^^^^^^^^^^^^^^^^^^^^^^
  File "/home/airflow/.local/lib/python3.12/site-packages/airflow/operators/python.py", line 252, in execute_callable
    return self.python_callable(*self.op_args, **self.op_kwargs)
           ^^^^^^^^^^^^^^^^^^^^^^^^^^^^^^^^^^^^^^^^^^^^^^^^^^^^^
  File "/opt/airflow/dags/etl.py", line 201, in connect_to_redshift
    with connection.cursor() as cursor:
         ^^^^^^^^^^
UnboundLocalError: cannot access local variable 'connection' where it is not associated with a value
[2024-06-04T22:46:42.870+0000] {taskinstance.py:1206} INFO - Marking task as UP_FOR_RETRY. dag_id=ingestion_data, task_id=conectando_con_redshift, run_id=manual__2024-06-04T22:46:32.936015+00:00, execution_date=20240604T224632, start_date=20240604T224642, end_date=20240604T224642
[2024-06-04T22:46:42.880+0000] {standard_task_runner.py:110} ERROR - Failed to execute job 13 for task conectando_con_redshift (cannot access local variable 'connection' where it is not associated with a value; 80)
[2024-06-04T22:46:42.920+0000] {local_task_job_runner.py:240} INFO - Task exited with return code 1
[2024-06-04T22:46:42.942+0000] {taskinstance.py:3498} INFO - 0 downstream tasks scheduled from follow-on schedule check
[2024-06-04T22:46:42.944+0000] {local_task_job_runner.py:222} INFO - ::endgroup::
